Workbook

Sheet BS
A1: ='BS Data'!C1 -> Allure of Peru
A2: Balance Sheet Analysis
A3: ='BS Data'!B3 -> As Of 12/31/2025
B5: CURRENT PERIOD
B6: Actual $
A7: Current Assets
A8: Cash | B8: =VLOOKUP(A8,'BS Data'!A8:B48,2,FALSE) -> 22699
A9: Accounts Receivable | B9: =VLOOKUP(A9,'BS Data'!A9:B49,2,FALSE) -> 1715902
A10: Allowance for Doubtful Account | B10: =VLOOKUP(A10,'BS Data'!A10:B50,2,FALSE) -> -50489
A11: Prepaid Expense | B11: =VLOOKUP(A11,'BS Data'!A11:B51,2,FALSE) -> 156097
A12: Intercompany Receivable | B12: =VLOOKUP(A12,'DTF & QuickCalc'!A57:B58,2,FALSE) -> 1279660.1
A13: Other Current Assets | B13: =VLOOKUP(A13,'BS Data'!A13:B53,2,FALSE) -> 1783
A14: TOTAL Current Assets | B14: =SUM(B8:B13) -> 3125652.1
A15: Fixed Assets
A16: Building and Land | B16: =VLOOKUP(A16,'BS Data'!A16:B56,2,FALSE) -> 3416
A17: Equipment | B17: =VLOOKUP(A17,'BS Data'!A17:B57,2,FALSE) -> 131927
A18: Furniture and Fixtures | B18: =VLOOKUP(A18,'BS Data'!A18:B58,2,FALSE) -> 4749
A19: Leasehold Improvements | B19: =VLOOKUP(A19,'BS Data'!A19:B59,2,FALSE) -> 685794
A20: CIP - Leasehold Improvements | B20: =VLOOKUP(A20,'BS Data'!A20:B60,2,FALSE) -> 0
A21: Vehicles | B21: =VLOOKUP(A21,'BS Data'!A21:B61,2,FALSE) -> 1099
A22: Organization Costs | B22: =VLOOKUP(A22,'BS Data'!A22:B62,2,FALSE) -> 23124
A23: Replacement Reserve | B23: =VLOOKUP(A23,'BS Data'!A23:B63,2,FALSE) -> 31590
A24: Loan Costs | B24: =VLOOKUP(A24,'BS Data'!A24:B64,2,FALSE) -> 0
A25: Less Accumulated Depreciation | B25: =VLOOKUP(A25,'BS Data'!A25:B65,2,FALSE) -> -180889
A26: TOTAL Fixed Assets | B26: =SUM(B16:B25) -> 700810
A27: Total Assets | B27: =B26+B14 -> 3826462.1
A28: Current Liabilities
A29: Accounts Payable | B29: =VLOOKUP(A29,'BS Data'!A29:B69,2,FALSE) -> 782460
A30: Credit Card Payable | B30: =VLOOKUP(A30,'BS Data'!A30:B70,2,FALSE) -> 0
A31: Accrued Expenses | B31: =VLOOKUP(A31,'BS Data'!A31:B71,2,FALSE) -> 231834
A32: Payroll Accruals and Liabilities | B32: =VLOOKUP(A32,'DTF & QuickCalc'!A63:B66,2,FALSE) -> 116658
A33: Line of Credit | B33: =VLOOKUP(A33,'BS Data'!A33:B73,2,FALSE) -> 850000
A34: Intercompany Payable | B34: =VLOOKUP(A34,'DTF & QuickCalc'!A57:B58,2,FALSE)-2 -> 1890823.7
A35: Other Current Liabilities | B35: =VLOOKUP(A35,'BS Data'!A35:B75,2,FALSE) -> 1446
A36: Resident Security Deposits | B36: =VLOOKUP(A36,'BS Data'!A36:B76,2,FALSE) -> 0
A37: TOTAL Current Liabilities | B37: =SUM(B29:B36) -> 3873221.7
A38: Long Term Liabilities | B38: =VLOOKUP(A38,'BS Data'!A38:B78,2,FALSE) -> 0
A39: TOTAL Liabilities | B39: =B37+B38 -> 3873221.7
A40: Equity
A41: Equity | B41: =VLOOKUP(A41,'BS Data'!A41:B81,2,FALSE) -> 759644
...

Sheet P&L
A1: =BS!A1 -> Allure of Peru
A2: Income Statement Detail
A3: ='P&L Data'!B3 -> 1/1/2025 to 12/31/2025
B5: CURRENT PERIOD | D5: YEAR TO DATE
B6: Actual $ | C6: Actual / Day | D6: Actual $ | E6: Actual / Day
A7: Revenue
A8: Medicaid | B8: =VLOOKUP(A8,'P&L Data'!A8:E150,2,FALSE) -> 4650290 | C8: =VLOOKUP(A8,'P&L Data'!A8:E150,3,FALSE) -> 279.75 | D8: =VLOOKUP(A8,'P&L Data'!A8:E150,4,FALSE) -> 4650290 | E8: =VLOOKUP(A8,'P&L Data'!A8:E150,5,FALSE) -> 279.75
A9: Hospice | B9: =VLOOKUP(A9,'P&L Data'!A9:E151,2,FALSE) -> 404354 | C9: =VLOOKUP(A9,'P&L Data'!A9:E151,3,FALSE) -> 278.29 | D9: =VLOOKUP(A9,'P&L Data'!A9:E151,4,FALSE) -> 404354 | E9: =VLOOKUP(A9,'P&L Data'!A9:E151,5,FALSE) -> 278.29
A10: Medicare A | B10: =VLOOKUP(A10,'P&L Data'!A10:E152,2,FALSE) -> 2480638 | C10: =VLOOKUP(A10,'P&L Data'!A10:E152,3,FALSE) -> 682.43 | D10: =VLOOKUP(A10,'P&L Data'!A10:E152,4,FALSE) -> 2480638 | E10: =VLOOKUP(A10,'P&L Data'!A10:E152,5,FALSE) -> 682.43
A11: Commercial Insurance | B11: =VLOOKUP(A11,'P&L Data'!A11:E153,2,FALSE) -> 924175 | C11: =VLOOKUP(A11,'P&L Data'!A11:E153,3,FALSE) -> 458.65 | D11: =VLOOKUP(A11,'P&L Data'!A11:E153,4,FALSE) -> 924175 | E11: =VLOOKUP(A11,'P&L Data'!A11:E153,5,FALSE) -> 458.65
A12: Private Pay | B12: =VLOOKUP(A12,'P&L Data'!A12:E154,2,FALSE) -> 1446974 | C12: =VLOOKUP(A12,'P&L Data'!A12:E154,3,FALSE) -> 295.24 | D12: =VLOOKUP(A12,'P&L Data'!A12:E154,4,FALSE) -> 1446974 | E12: =VLOOKUP(A12,'P&L Data'!A12:E154,5,FALSE) -> 295.24
A13: Veteran Affairs | B13: =VLOOKUP(A13,'P&L Data'!A13:E155,2,FALSE) -> 0 | C13: =VLOOKUP(A13,'P&L Data'!A13:E155,3,FALSE) -> 0 | D13: =VLOOKUP(A13,'P&L Data'!A13:E155,4,FALSE) -> 0 | E13: =VLOOKUP(A13,'P&L Data'!A13:E155,5,FALSE) -> 0
A14: Medicare / Managed Care B | B14: =VLOOKUP(A14,'P&L Data'!A14:E156,2,FALSE) -> 297113 | C14: =VLOOKUP(A14,'P&L Data'!A14:E156,3,FALSE) -> 0 | D14: =VLOOKUP(A14,'P&L Data'!A14:E156,4,FALSE) -> 297113 | E14: =VLOOKUP(A14,'P&L Data'!A14:E156,5,FALSE) -> 0
A15: Private Pay Independent Living | B15: =VLOOKUP(A15,'P&L Data'!A15:E157,2,FALSE) -> 0 | C15: =VLOOKUP(A15,'P&L Data'!A15:E157,3,FALSE) -> 0 | D15: =VLOOKUP(A15,'P&L Data'!A15:E157,4,FALSE) -> 0 | E15: =VLOOKUP(A15,'P&L Data'!A15:E157,5,FALSE) -> 0
A16: Home Care Income | B16: =VLOOKUP(A16,'P&L Data'!A16:E158,2,FALSE) -> 0 | C16: =VLOOKUP(A16,'P&L Data'!A16:E158,3,FALSE) -> 0 | D16: =VLOOKUP(A16,'P&L Data'!A16:E158,4,FALSE) -> 0 | E16: =VLOOKUP(A16,'P&L Data'!A16:E158,5,FALSE) -> 0
A17: Daily Training Program | B17: =VLOOKUP(A17,'P&L Data'!A17:E159,2,FALSE) -> 0 | C17: =VLOOKUP(A17,'P&L Data'!A17:E159,3,FALSE) -> 0 | D17: =VLOOKUP(A17,'P&L Data'!A17:E159,4,FALSE) -> 0 | E17: =VLOOKUP(A17,'P&L Data'!A17:E159,5,FALSE) -> 0
A18: Other | B18: =VLOOKUP(A18,'P&L Data'!A18:E160,2,FALSE) -> 5276 | C18: =VLOOKUP(A18,'P&L Data'!A18:E160,3,FALSE) -> 0 | D18: =VLOOKUP(A18,'P&L Data'!A18:E160,4,FALSE) -> 5276 | E18: =VLOOKUP(A18,'P&L Data'!A18:E160,5,FALSE) -> 0
A19: Stimulus Income | B19: =VLOOKUP(A19,'P&L Data'!A19:E161,2,FALSE) -> 0 | C19: =VLOOKUP(A19,'P&L Data'!A19:E161,3,FALSE) -> 0 | D19: =VLOOKUP(A19,'P&L Data'!A19:E161,4,FALSE) -> 0 | E19: =VLOOKUP(A19,'P&L Data'!A19:E161,5,FALSE) -> 0
... A21: TOTAL Revenue | B21: =VLOOKUP(A21,'P&L Data'!A21:E163,2,FALSE) -> 10424247 | C21: =VLOOKUP(A21,'P&L Data'!A21:E163,3,FALSE) -> 364.14 | D21: =VLOOKUP(A21,'P&L Data'!A21:E163,4,FALSE) -> 10424247 | E21: =VLOOKUP(A21,'P&L Data'!A21:E163,5,FALSE) -> 364.14
A22: Patient Days
A23: Medicaid | B23: =VLOOKUP(A23,'P&L Data'!A23:E165,2,FALSE) -> 16663 | C23: =VLOOKUP(A23,'P&L Data'!A23:E165,3,FALSE) -> 0 | D23: =VLOOKUP(A23,'P&L Data'!A23:E165,4,FALSE) -> 16663 | E23: =VLOOKUP(A23,'P&L Data'!A23:E165,5,FALSE) -> 0
A24: Hospice | B24: =VLOOKUP(A24,'P&L Data'!A24:E166,2,FALSE) -> 1453 | C24: =VLOOKUP(A24,'P&L Data'!A24:E166,3,FALSE) -> 0 | D24: =VLOOKUP(A24,'P&L Data'!A24:E166,4,FALSE) -> 1453 | E24: =VLOOKUP(A24,'P&L Data'!A24:E166,5,FALSE) -> 0
A25: Medicare A | B25: =VLOOKUP(A25,'P&L Data'!A25:E167,2,FALSE) -> 3635 | C25: =VLOOKUP(A25,'P&L Data'!A25:E167,3,FALSE) -> 0 | D25: =VLOOKUP(A25,'P&L Data'!A25:E167,4,FALSE) -> 3635 | E25: =VLOOKUP(A25,'P&L Data'!A25:E167,5,FALSE) -> 0
A26: Commercial Insurance | B26: =VLOOKUP(A26,'P&L Data'!A26:E168,2,FALSE) -> 2015 | C26: =VLOOKUP(A26,'P&L Data'!A26:E168,3,FALSE) -> 0 | D26: =VLOOKUP(A26,'P&L Data'!A26:E168,4,FALSE) -> 2015 | E26: =VLOOKUP(A26,'P&L Data'!A26:E168,5,FALSE) -> 0
A27: Private Pay | B27: =VLOOKUP(A27,'P&L Data'!A27:E169,2,FALSE) -> 4894 | C27: =VLOOKUP(A27,'P&L Data'!A27:E169,3,FALSE) -> 0 | D27: =VLOOKUP(A27,'P&L Data'!A27:E169,4,FALSE) -> 4894 | E27: =VLOOKUP(A27,'P&L Data'!A27:E169,5,FALSE) -> 0
A28: Veteran Affairs | B28: =VLOOKUP(A28,'P&L Data'!A28:E170,2,FALSE) -> 0 | C28: =VLOOKUP(A28,'P&L Data'!A28:E170,3,FALSE) -> 0 | D28: =VLOOKUP(A28,'P&L Data'!A28:E170,4,FALSE) -> 0 | E28: =VLOOKUP(A28,'P&L Data'!A28:E170,5,FALSE) -> 0
A29: Independent Living | B29: =VLOOKUP(A29,'P&L Data'!A29:E171,2,FALSE) -> 0 | C29: =VLOOKUP(A29,'P&L Data'!A29:E171,3,FALSE) -> 0 | D29: =VLOOKUP(A29,'P&L Data'!A29:E171,4,FALSE) -> 0 | E29: =VLOOKUP(A29,'P&L Data'!A29:E171,5,FALSE) -> 0
A30: TOTAL Patient Days | B30: =VLOOKUP(A30,'P&L Data'!A30:E172,2,FALSE) -> 28660 | C30: =VLOOKUP(A30,'P&L Data'!A30:E172,3,FALSE) -> 0 | D30: =VLOOKUP(A30,'P&L Data'!A30:E172,4,FALSE) -> 28660 | E30: =VLOOKUP(A30,'P&L Data'!A30:E172,5,FALSE) -> 0
A31: Nursing & Medical
A32: Director Of Nursing | B32: =VLOOKUP(A32,'P&L Data'!A32:E174,2,FALSE) -> 105946 | C32: =VLOOKUP(A32,'P&L Data'!A32:E174,3,FALSE) -> 3.7 | D32: =VLOOKUP(A32,'P&L Data'!A32:E174,4,FALSE) -> 105946 | E32: =VLOOKUP(A32,'P&L Data'!A32:E174,5,FALSE) -> 3.7
A33: Assistant Director Of Nursing | B33: =VLOOKUP(A33,'P&L Data'!A33:E175,2,FALSE) -> 85613 | C33: =VLOOKUP(A33,'P&L Data'!A33:E175,3,FALSE) -> 2.99 | D33: =VLOOKUP(A33,'P&L Data'!A33:E175,4,FALSE) -> 85613 | E33: =VLOOKUP(A33,'P&L Data'!A33:E175,5,FALSE) -> 2.99
A34: Payroll RN | B34: =VLOOKUP(A34,'P&L Data'!A34:E176,2,FALSE) -> 800771 | C34: =VLOOKUP(A34,'P&L Data'!A34:E176,3,FALSE) -> 27.97 | D34: =VLOOKUP(A34,'P&L Data'!A34:E176,4,FALSE) -> 800771 | E34: =VLOOKUP(A34,'P&L Data'!A34:E176,5,FALSE) -> 27.97
A35: Payroll LPN | B35: =VLOOKUP(A35,'P&L Data'!A35:E177,2,FALSE) -> 442824 | C35: =VLOOKUP(A35,'P&L Data'!A35:E177,3,FALSE) -> 15.47 | D35: =VLOOKUP(A35,'P&L Data'!A35:E177,4,FALSE) -> 442824 | E35: =VLOOKUP(A35,'P&L Data'!A35:E177,5,FALSE) -> 15.47
A36: Payroll Aides & Orderlies | B36: =VLOOKUP(A36,'P&L Data'!A36:E178,2,FALSE) -> 1861774 | C36: =VLOOKUP(A36,'P&L Data'!A36:E178,3,FALSE) -> 65.04 | D36: =VLOOKUP(A36,'P&L Data'!A36:E178,4,FALSE) -> 1861774 | E36: =VLOOKUP(A36,'P&L Data'!A36:E178,5,FALSE) -> 65.04
A37: Payroll Nursing Clerical | B37: =VLOOKUP(A37,'P&L Data'!A37:E179,2,FALSE) -> 92496 | C37: =VLOOKUP(A37,'P&L Data'!A37:E179,3,FALSE) -> 3.23 | D37: =VLOOKUP(A37,'P&L Data'!A37:E179,4,FALSE) -> 92496 | E37: =VLOOKUP(A37,'P&L Data'!A37:E179,5,FALSE) -> 3.23
A38: Payroll Medical Records | B38: =VLOOKUP(A38,'P&L Data'!A38:E180,2,FALSE) -> 0 | C38: =VLOOKUP(A38,'P&L Data'!A38:E180,3,FALSE) -> 0 | D38: =VLOOKUP(A38,'P&L Data'!A38:E180,4,FALSE) -> 0 | E38: =VLOOKUP(A38,'P&L Data'!A38:E180,5,FALSE) -> 0
A39: Contract RN | B39: =VLOOKUP(A39,'P&L Data'!A39:E181,2,FALSE) -> 177691 | C39: =VLOOKUP(A39,'P&L Data'!A39:E181,3,FALSE) -> 6.21 | D39: =VLOOKUP(A39,'P&L Data'!A39:E181,4,FALSE) -> 177691 | E39: =VLOOKUP(A39,'P&L Data'!A39:E181,5,FALSE) -> 6.21
A40: Contract LPN | B40: =VLOOKUP(A40,'P&L Data'!A40:E182,2,FALSE) -> 18418 | C40: =VLOOKUP(A40,'P&L Data'!A40:E182,3,FALSE) -> 0.64 | D40: =VLOOKUP(A40,'P&L Data'!A40:E182,4,FALSE) -> 18418 | E40: =VLOOKUP(A40,'P&L Data'!A40:E182,5,FALSE) -> 0.64
A41: Contract Aides & Orderlies | B41: =VLOOKUP(A41,'P&L Data'!A41:E183,2,FALSE) -> 167869 | C41: =VLOOKUP(A41,'P&L Data'!A41:E183,3,FALSE) -> 5.86 | D41: =VLOOKUP(A41,'P&L Data'!A41:E183,4,FALSE) -> 167869 | E41: =VLOOKUP(A41,'P&L Data'!A41:E183,5,FALSE) -> 5.86
A42: Medical Supplies | B42: =VLOOKUP(A42,'P&L Data'!A42:E184,2,FALSE) -> 107643 | C42: =VLOOKUP(A42,'P&L Data'!A42:E184,3,FALSE) -> 3.76 | D42: =VLOOKUP(A42,'P&L Data'!A42:E184,4,FALSE) -> 107643 | E42: =VLOOKUP(A42,'P&L Data'!A42:E184,5,FALSE) -> 3.76
...

Sheet P&L Detail Trending
A1: =BS!A1 -> Allure of Peru
A2: Income Statement Detail Trending
A3: ='P&L Trending Data'!B4 -> 1/1/2025 to 12/31/2025
B5: ='DTF & QuickCalc'!A72 -> 45658 | D5: =EDATE(B5,1) -> 45689 | F5: =EDATE(D5,1) -> 45717 | H5: =EDATE(F5,1) -> 45748 | J5: =EDATE(H5,1) -> 45778 | L5: =EDATE(J5,1) -> 45809 | N5: =EDATE(L5,1) -> 45839 | P5: =EDATE(N5,1) -> 45870 | R5: =EDATE(P5,1) -> 45901 | T5: =EDATE(R5,1) -> 45931 | V5: =EDATE(T5,1) -> 45962 | X5: =EDATE(V5,1) -> 45992 | Z5: TOTALS
B6: Actual $ | C6: Actual / Day | D6: Actual $ | E6: Actual / Day | F6: Actual $ | G6: Actual / Day | H6: Actual $ | I6: Actual / Day | J6: Actual $ | K6: Actual / Day | L6: Actual $ | M6: Actual / Day | N6: Actual $ | O6: Actual / Day | P6: Actual $ | Q6: Actual / Day | R6: Actual $ | S6: Actual / Day | T6: Actual $ | U6: Actual / Day | V6: Actual $ | W6: Actual / Day | X6: Actual $ | Y6: Actual / Day | Z6: Actual $ | AA6: Actual / Day
A7: Revenue
A8: Medicaid | B8: {=_xlfn.XLOOKUP(A8,'P&L Trending Data'!A9:A149,'P&L Trending Data'!B9:Y149)} -> 388276 | C8: 276.75 | D8: 408258 | E8: 279.82 | F8: 406113 | G8: 278.35 | H8: 370960 | I8: 282.53 | J8: 371972 | K8: 282.87 | L8: 407087 | M8: 282.11 | N8: 395127 | O8: 295.98 | P8: 413088 | Q8: 295.7 | R8: 410913 | S8: 296.05 | T8: 369135 | U8: 262.73 | V8: 320350 | W8: 261.3 | X8: 389012 | Y8: 262.85 | Z8: =B8+D8+F8+H8+J8+L8+N8+P8+R8+T8+V8+X8 -> 4650291 | AA8: =C8+E8+G8+I8+K8+M8+O8+Q8+S8+U8+W8+Y8 -> 3357.04
A9: Hospice | B9: {=_xlfn.XLOOKUP(A9,'P&L Trending Data'!A10:A150,'P&L Trending Data'!B10:Y150)} -> 23801 | C9: 276.76 | D9: 26023 | E9: 279.82 | F9: 33402 | G9: 278.35 | H9: 32504 | I9: 282.64 | J9: 37308 | K9: 282.64 | L9: 18649 | M9: 286.91 | N9: 27562 | O9: 296.37 | P9: 41492 | Q9: 296.37 | R9: 42085 | S9: 296.37 | T9: 37000 | U9: 262.41 | V9: 30470 | W9: 253.92 | X9: 54056 | Y9: 262.41 | Z9: =B9+D9+F9+H9+J9+L9+N9+P9+R9+T9+V9+X9 -> 404352 | AA9: =C9+E9+G9+I9+K9+M9+O9+Q9+S9+U9+W9+Y9 -> 3354.97
A10: Medicare A | B10: {=_xlfn.XLOOKUP(A10,'P&L Trending Data'!A11:A151,'P&L Trending Data'!B11:Y151)} -> 276629 | C10: 726.06 | D10: 190410 | E10: 721.25 | F10: 271459 | G10: 696.05 | H10: 231688 | I10: 675.47 | J10: 234861 | K10: 727.13 | L10: 188683 | M10: 681.16 | N10: 195908 | O10: 653.03 | P10: 150286 | Q10: 615.93 | R10: 180454 | S10: 649.11 | T10: 173470 | U10: 649.7 | V10: 165678 | W10: 676.24 | X10: 221112 | Y10: 684.56 | Z10: =B10+D10+F10+H10+J10+L10+N10+P10+R10+T10+V10+X10 -> 2480638 | AA10: =C10+E10+G10+I10+K10+M10+O10+Q10+S10+U10+W10+Y10 -> 8155.69
A11: Commercial Insurance | B11: {=_xlfn.XLOOKUP(A11,'P&L Trending Data'!A12:A152,'P&L Trending Data'!B12:Y152)} -> 106231 | C11: 440.79 | D11: 113904 | E11: 433.09 | F11: 112617 | G11: 415.56 | H11: 58193 | I11: 476.99 | J11: 45675 | K11: 400.66 | L11: 43336 | M11: 577.81 | N11: 52479 | O11: 460.34 | P11: 77254 | Q11: 508.25 | R11: 91873 | S11: 419.51 | T11: 53007 | U11: 486.3 | V11: 50226 | W11: 469.41 | X11: 119379 | Y11: 523.59 | Z11: =B11+D11+F11+H11+J11+L11+N11+P11+R11+T11+V11+X11 -> 924174 | AA11: =C11+E11+G11+I11+K11+M11+O11+Q11+S11+U11+W11+Y11 -> 5612.3
A12: Private Pay | B12: {=_xlfn.XLOOKUP(A12,'P&L Trending Data'!A13:A153,'P&L Trending Data'!B13:Y153)} -> 138594 | C12: 304.6 | D12: 98035 | E12: 304.46 | F12: 102135 | G12: 289.34 | H12: 103587 | I12: 287.74 | J12: 167586 | K12: 287.95 | L12: 140418 | M12: 312.04 | N12: 155881 | O12: 292.46 | P12: 123863 | Q12: 306.59 | R12: 130438 | S12: 299.86 | T12: 104916 | U12: 303.22 | V12: 120531 | W12: 269.64 | X12: 60990 | Y12: 285 | Z12: =B12+D12+F12+H12+J12+L12+N12+P12+R12+T12+V12+X12 -> 1446974 | AA12: =C12+E12+G12+I12+K12+M12+O12+Q12+S12+U12+W12+Y12 -> 3542.9
A13: Veteran Affairs | B13: {=_xlfn.XLOOKUP(A13,'P&L Trending Data'!A14:A154,'P&L Trending Data'!B14:Y154)} -> 0 | C13: 0 | D13: 0 | E13: 0 | F13: 0 | G13: 0 | H13: 0 | I13: 0 | J13: 0 | K13: 0 | L13: 0 | M13: 0 | N13: 0 | O13: 0 | P13: 0 | Q13: 0 | R13: 0 | S13: 0 | T13: 0 | U13: 0 | V13: 0 | W13: 0 | X13: 0 | Y13: 0 | Z13: =B13+D13+F13+H13+J13+L13+N13+P13+R13+T13+V13+X13 -> 0 | AA13: =C13+E13+G13+I13+K13+M13+O13+Q13+S13+U13+W13+Y13 -> 0
A14: Medicare / Managed Care B | B14: {=_xlfn.XLOOKUP(A14,'P&L Trending Data'!A15:A155,'P&L Trending Data'!B15:Y155)} -> 22407 | C14: 0 | D14: 1600 | E14: 0 | F14: 38819 | G14: 0 | H14: 21411 | I14: 0 | J14: 26503 | K14: 0 | L14: 27290 | M14: 0 | N14: 31718 | O14: 0 | P14: 29662 | Q14: 0 | R14: 24022 | S14: 0 | T14: 32306 | U14: 0 | V14: 18907 | W14: 0 | X14: 22468 | Y14: 0 | Z14: =B14+D14+F14+H14+J14+L14+N14+P14+R14+T14+V14+X14 -> 297113 | AA14: =C14+E14+G14+I14+K14+M14+O14+Q14+S14+U14+W14+Y14 -> 0
A15: Private Pay Independent Living | B15: {=_xlfn.XLOOKUP(A15,'P&L Trending Data'!A16:A156,'P&L Trending Data'!B16:Y156)} -> 0 | C15: 0 | D15: 0 | E15: 0 | F15: 0 | G15: 0 | H15: 0 | I15: 0 | J15: 0 | K15: 0 | L15: 0 | M15: 0 | N15: 0 | O15: 0 | P15: 0 | Q15: 0 | R15: 0 | S15: 0 | T15: 0 | U15: 0 | V15: 0 | W15: 0 | X15: 0 | Y15: 0 | Z15: =B15+D15+F15+H15+J15+L15+N15+P15+R15+T15+V15+X15 -> 0 | AA15: =C15+E15+G15+I15+K15+M15+O15+Q15+S15+U15+W15+Y15 -> 0
A16: Home Care Income | B16: {=_xlfn.XLOOKUP(A16,'P&L Trending Data'!A17:A157,'P&L Trending Data'!B17:Y157)} -> 0 | C16: 0 | D16: 0 | E16: 0 | F16: 0 | G16: 0 | H16: 0 | I16: 0 | J16: 0 | K16: 0 | L16: 0 | M16: 0 | N16: 0 | O16: 0 | P16: 0 | Q16: 0 | R16: 0 | S16: 0 | T16: 0 | U16: 0 | V16: 0 | W16: 0 | X16: 0 | Y16: 0 | Z16: =B16+D16+F16+H16+J16+L16+N16+P16+R16+T16+V16+X16 -> 0 | AA16: =C16+E16+G16+I16+K16+M16+O16+Q16+S16+U16+W16+Y16 -> 0
A17: Daily Training Program | B17: {=_xlfn.XLOOKUP(A17,'P&L Trending Data'!A18:A158,'P&L Trending Data'!B18:Y158)} -> 0 | C17: 0 | D17: 0 | E17: 0 | F17: 0 | G17: 0 | H17: 0 | I17: 0 | J17: 0 | K17: 0 | L17: 0 | M17: 0 | N17: 0 | O17: 0 | P17: 0 | Q17: 0 | R17: 0 | S17: 0 | T17: 0 | U17: 0 | V17: 0 | W17: 0 | X17: 0 | Y17: 0 | Z17: =B17+D17+F17+H17+J17+L17+N17+P17+R17+T17+V17+X17 -> 0 | AA17: =C17+E17+G17+I17+K17+M17+O17+Q17+S17+U17+W17+Y17 -> 0
A18: Other | B18: {=_xlfn.XLOOKUP(A18,'P&L Trending Data'!A19:A159,'P&L Trending Data'!B19:Y159)} -> 313 | C18: 0 | D18: 1116 | E18: 0 | F18: 84 | G18: 0 | H18: 82 | I18: 0 | J18: 96 | K18: 0 | L18: 114 | M18: 0 | N18: 87 | O18: 0 | P18: 1923 | Q18: 0 | R18: 139 | S18: 0 | T18: 635 | U18: 0 | V18: 578 | W18: 0 | X18: 108 | Y18: 0 | Z18: =B18+D18+F18+H18+J18+L18+N18+P18+R18+T18+V18+X18 -> 5275 | AA18: =C18+E18+G18+I18+K18+M18+O18+Q18+S18+U18+W18+Y18 -> 0
A19: Stimulus Income | B19: {=_xlfn.XLOOKUP(A19,'P&L Trending Data'!A20:A160,'P&L Trending Data'!B20:Y160)} -> 0 | C19: 0 | D19: 0 | E19: 0 | F19: 0 | G19: 0 | H19: 0 | I19: 0 | J19: 0 | K19: 0 | L19: 0 | M19: 0 | N19: 0 | O19: 0 | P19: 0 | Q19: 0 | R19: 0 | S19: 0 | T19: 0 | U19: 0 | V19: 0 | W19: 0 | X19: 0 | Y19: 0 | Z19: =B19+D19+F19+H19+J19+L19+N19+P19+R19+T19+V19+X19 -> 0 | AA19: =C19+E19+G19+I19+K19+M19+O19+Q19+S19+U19+W19+Y19 -> 0
... A21: TOTAL Revenue | B21: {=_xlfn.XLOOKUP(A21,'P&L Trending Data'!A22:A162,'P&L Trending Data'!B22:Y162)} -> 974758 | C21: 379.87 | D21: 857852 | E21: 357.29 | F21: 983136 | G21: 379.15 | H21: 835326 | I21: 370.76 | J21: 900903 | K21: 365.33 | L21: 842479 | M21: 364.71 | N21: 877308 | O21: 369.39 | P21: 856113 | Q21: 366.33 | R21: 898468 | S21: 364.93 | T21: 789014 | U21: 347.89 | V21: 723906 | W21: 337.49 | X21: 884982 | Y21: 361.07 | Z21: =B21+D21+F21+H21+J21+L21+N21+P21+R21+T21+V21+X21 -> 10424245 | AA21: =C21+E21+G21+I21+K21+M21+O21+Q21+S21+U21+W21+Y21 -> 4364.21
A22: Patient Days
A23: Medicaid | B23: {=_xlfn.XLOOKUP(A23,'P&L Trending Data'!A24:A164,'P&L Trending Data'!B24:Y164)} -> 1445 | C23: 0 | D23: 1459 | E23: 0 | F23: 1452 | G23: 0 | H23: 1313 | I23: 0 | J23: 1315 | K23: 0 | L23: 1449 | M23: 0 | N23: 1335 | O23: 0 | P23: 1397 | Q23: 0 | R23: 1388 | S23: 0 | T23: 1405 | U23: 0 | V23: 1225 | W23: 0 | X23: 1480 | Y23: 0 | Z23: =B23+D23+F23+H23+J23+L23+N23+P23+R23+T23+V23+X23 -> 16663 | AA23: -
A24: Hospice | B24: {=_xlfn.XLOOKUP(A24,'P&L Trending Data'!A25:A165,'P&L Trending Data'!B25:Y165)} -> 86 | C24: 0 | D24: 93 | E24: 0 | F24: 120 | G24: 0 | H24: 115 | I24: 0 | J24: 132 | K24: 0 | L24: 65 | M24: 0 | N24: 93 | O24: 0 | P24: 140 | Q24: 0 | R24: 142 | S24: 0 | T24: 141 | U24: 0 | V24: 120 | W24: 0 | X24: 206 | Y24: 0 | Z24: =B24+D24+F24+H24+J24+L24+N24+P24+R24+T24+V24+X24 -> 1453 | AA24: -
A25: Medicare A | B25: {=_xlfn.XLOOKUP(A25,'P&L Trending Data'!A26:A166,'P&L Trending Data'!B26:Y166)} -> 381 | C25: 0 | D25: 264 | E25: 0 | F25: 390 | G25: 0 | H25: 343 | I25: 0 | J25: 323 | K25: 0 | L25: 277 | M25: 0 | N25: 300 | O25: 0 | P25: 244 | Q25: 0 | R25: 278 | S25: 0 | T25: 267 | U25: 0 | V25: 245 | W25: 0 | X25: 323 | Y25: 0 | Z25: =B25+D25+F25+H25+J25+L25+N25+P25+R25+T25+V25+X25 -> 3635 | AA25: -
A26: Commercial Insurance | B26: {=_xlfn.XLOOKUP(A26,'P&L Trending Data'!A27:A167,'P&L Trending Data'!B27:Y167)} -> 241 | C26: 0 | D26: 263 | E26: 0 | F26: 271 | G26: 0 | H26: 122 | I26: 0 | J26: 114 | K26: 0 | L26: 75 | M26: 0 | N26: 114 | O26: 0 | P26: 152 | Q26: 0 | R26: 219 | S26: 0 | T26: 109 | U26: 0 | V26: 107 | W26: 0 | X26: 228 | Y26: 0 | Z26: =B26+D26+F26+H26+J26+L26+N26+P26+R26+T26+V26+X26 -> 2015 | AA26: -
A27: Private Pay | B27: {=_xlfn.XLOOKUP(A27,'P&L Trending Data'!A28:A168,'P&L Trending Data'!B28:Y168)} -> 455 | C27: 0 | D27: 322 | E27: 0 | F27: 353 | G27: 0 | H27: 360 | I27: 0 | J27: 582 | K27: 0 | L27: 450 | M27: 0 | N27: 533 | O27: 0 | P27: 404 | Q27: 0 | R27: 435 | S27: 0 | T27: 340 | U27: 0 | V27: 442 | W27: 0 | X27: 218 | Y27: 0 | Z27: =B27+D27+F27+H27+J27+L27+N27+P27+R27+T27+V27+X27 -> 4894 | AA27: -
A28: Veteran Affairs | B28: {=_xlfn.XLOOKUP(A28,'P&L Trending Data'!A29:A169,'P&L Trending Data'!B29:Y169)} -> 0 | C28: 0 | D28: 0 | E28: 0 | F28: 0 | G28: 0 | H28: 0 | I28: 0 | J28: 0 | K28: 0 | L28: 0 | M28: 0 | N28: 0 | O28: 0 | P28: 0 | Q28: 0 | R28: 0 | S28: 0 | T28: 0 | U28: 0 | V28: 0 | W28: 0 | X28: 0 | Y28: 0 | Z28: =B28+D28+F28+H28+J28+L28+N28+P28+R28+T28+V28+X28 -> 0 | AA28: -
A29: Independent Living | B29: {=_xlfn.XLOOKUP(A29,'P&L Trending Data'!A30:A170,'P&L Trending Data'!B30:Y170)} -> 0 | C29: 0 | D29: 0 | E29: 0 | F29: 0 | G29: 0 | H29: 0 | I29: 0 | J29: 0 | K29: 0 | L29: 0 | M29: 0 | N29: 0 | O29: 0 | P29: 0 | Q29: 0 | R29: 0 | S29: 0 | T29: 0 | U29: 0 | V29: 0 | W29: 0 | X29: 0 | Y29: 0 | Z29: =B29+D29+F29+H29+J29+L29+N29+P29+R29+T29+V29+X29 -> 0 | AA29: -
A30: TOTAL Patient Days | B30: {=_xlfn.XLOOKUP(A30,'P&L Trending Data'!A31:A171,'P&L Trending Data'!B31:Y171)} -> 2608 | C30: 0 | D30: 2401 | E30: 0 | F30: 2586 | G30: 0 | H30: 2253 | I30: 0 | J30: 2466 | K30: 0 | L30: 2316 | M30: 0 | N30: 2375 | O30: 0 | P30: 2337 | Q30: 0 | R30: 2462 | S30: 0 | T30: 2262 | U30: 0 | V30: 2139 | W30: 0 | X30: 2455 | Y30: 0 | Z30: =B30+D30+F30+H30+J30+L30+N30+P30+R30+T30+V30+X30 -> 28660 | AA30: =C30+E30+G30+I30+K30+M30+O30+Q30+S30+U30+W30+Y30 -> 0
A31: Nursing & Medical
A32: Director Of Nursing | B32: {=_xlfn.XLOOKUP(A32,'P&L Trending Data'!A33:A173,'P&L Trending Data'!B33:Y173)} -> 9212 | C32: 3.59 | D32: 7717 | E32: 3.21 | F32: 8952 | G32: 3.45 | H32: 8492 | I32: 3.77 | J32: 8997 | K32: 3.65 | L32: 8509 | M32: 3.68 | N32: 10067 | O32: 4.24 | P32: 8597 | Q32: 3.68 | R32: 8438 | S32: 3.43 | T32: 9040 | U32: 3.99 | V32: 9054 | W32: 4.22 | X32: 8871 | Y32: 3.62 | Z32: =B32+D32+F32+H32+J32+L32+N32+P32+R32+T32+V32+X32 -> 105946 | AA32: =C32+E32+G32+I32+K32+M32+O32+Q32+S32+U32+W32+Y32 -> 44.53
A33: Assistant Director Of Nursing | B33: {=_xlfn.XLOOKUP(A33,'P&L Trending Data'!A34:A174,'P&L Trending Data'!B34:Y174)} -> 7877 | C33: 3.07 | D33: 7354 | E33: 3.06 | F33: 7832 | G33: 3.02 | H33: 7552 | I33: 3.35 | J33: 8298 | K33: 3.36 | L33: 7532 | M33: 3.26 | N33: 7601 | O33: 3.2 | P33: 7638 | Q33: 3.27 | R33: 6659 | S33: 2.7 | T33: 1904 | U33: 0.84 | V33: 6738 | W33: 3.14 | X33: 8630 | Y33: 3.52 | Z33: =B33+D33+F33+H33+J33+L33+N33+P33+R33+T33+V33+X33 -> 85615 | AA33: =C33+E33+G33+I33+K33+M33+O33+Q33+S33+U33+W33+Y33 -> 35.79
A34: Payroll RN | B34: {=_xlfn.XLOOKUP(A34,'P&L Trending Data'!A35:A175,'P&L Trending Data'!B35:Y175)} -> 65236 | C34: 25.42 | D34: 60365 | E34: 25.14 | F34: 68632 | G34: 26.47 | H34: 69671 | I34: 30.92 | J34: 71475 | K34: 28.98 | L34: 69227 | M34: 29.97 | N34: 72869 | O34: 30.68 | P34: 66824 | Q34: 28.59 | R34: 64087 | S34: 26.03 | T34: 66427 | U34: 29.29 | V34: 64275 | W34: 29.97 | X34: 61682 | Y34: 25.17 | Z34: =B34+D34+F34+H34+J34+L34+N34+P34+R34+T34+V34+X34 -> 800770 | AA34: =C34+E34+G34+I34+K34+M34+O34+Q34+S34+U34+W34+Y34 -> 336.63
A35: Payroll LPN | B35: {=_xlfn.XLOOKUP(A35,'P&L Trending Data'!A36:A176,'P&L Trending Data'!B36:Y176)} -> 36740 | C35: 14.32 | D35: 36131 | E35: 15.05 | F35: 35983 | G35: 13.88 | H35: 33791 | I35: 15 | J35: 33989 | K35: 13.78 | L35: 40210 | M35: 17.41 | N35: 34691 | O35: 14.61 | P35: 34825 | Q35: 14.9 | R35: 35716 | S35: 14.51 | T35: 40897 | U35: 18.03 | V35: 39372 | W35: 18.36 | X35: 40479 | Y35: 16.52 | Z35: =B35+D35+F35+H35+J35+L35+N35+P35+R35+T35+V35+X35 -> 442824 | AA35: =C35+E35+G35+I35+K35+M35+O35+Q35+S35+U35+W35+Y35 -> 186.37
A36: Payroll Aides & Orderlies | B36: {=_xlfn.XLOOKUP(A36,'P&L Trending Data'!A37:A177,'P&L Trending Data'!B37:Y177)} -> 158997 | C36: 61.96 | D36: 131266 | E36: 54.67 | F36: 156709 | G36: 60.44 | H36: 157935 | I36: 70.1 | J36: 171345 | K36: 69.48 | L36: 162985 | M36: 70.56 | N36: 155904 | O36: 65.64 | P36: 145993 | Q36: 62.47 | R36: 154712 | S36: 62.84 | T36: 142246 | U36: 62.72 | V36: 151314 | W36: 70.54 | X36: 172369 | Y36: 70.33 | Z36: =B36+D36+F36+H36+J36+L36+N36+P36+R36+T36+V36+X36 -> 1861775 | AA36: =C36+E36+G36+I36+K36+M36+O36+Q36+S36+U36+W36+Y36 -> 781.75
A37: Payroll Nursing Clerical | B37: {=_xlfn.XLOOKUP(A37,'P&L Trending Data'!A38:A178,'P&L Trending Data'!B38:Y178)} -> 7723 | C37: 3.01 | D37: 7800 | E37: 3.25 | F37: 7670 | G37: 2.96 | H37: 7340 | I37: 3.26 | J37: 8444 | K37: 3.42 | L37: 7123 | M37: 3.08 | N37: 7715 | O37: 3.25 | P37: 7615 | Q37: 3.26 | R37: 7479 | S37: 3.04 | T37: 7624 | U37: 3.36 | V37: 7485 | W37: 3.49 | X37: 8478 | Y37: 3.46 | Z37: =B37+D37+F37+H37+J37+L37+N37+P37+R37+T37+V37+X37 -> 92496 | AA37: =C37+E37+G37+I37+K37+M37+O37+Q37+S37+U37+W37+Y37 -> 38.84
A38: Payroll Medical Records | B38: {=_xlfn.XLOOKUP(A38,'P&L Trending Data'!A39:A179,'P&L Trending Data'!B39:Y179)} -> 0 | C38: 0 | D38: 0 | E38: 0 | F38: 0 | G38: 0 | H38: 0 | I38: 0 | J38: 0 | K38: 0 | L38: 0 | M38: 0 | N38: 0 | O38: 0 | P38: 0 | Q38: 0 | R38: 0 | S38: 0 | T38: 0 | U38: 0 | V38: 0 | W38: 0 | X38: 0 | Y38: 0 | Z38: =B38+D38+F38+H38+J38+L38+N38+P38+R38+T38+V38+X38 -> 0 | AA38: =C38+E38+G38+I38+K38+M38+O38+Q38+S38+U38+W38+Y38 -> 0
A39: Contract RN | B39: {=_xlfn.XLOOKUP(A39,'P&L Trending Data'!A40:A180,'P&L Trending Data'!B40:Y180)} -> 24990 | C39: 9.74 | D39: 10031 | E39: 4.18 | F39: 15243 | G39: 5.88 | H39: 4530 | I39: 2.01 | J39: 15581 | K39: 6.32 | L39: 13713 | M39: 5.94 | N39: 13755 | O39: 5.79 | P39: 5793 | Q39: 2.48 | R39: 26888 | S39: 10.92 | T39: 12299 | U39: 5.42 | V39: 8223 | W39: 3.83 | X39: 26644 | Y39: 10.87 | Z39: =B39+D39+F39+H39+J39+L39+N39+P39+R39+T39+V39+X39 -> 177690 | AA39: =C39+E39+G39+I39+K39+M39+O39+Q39+S39+U39+W39+Y39 -> 73.38
A40: Contract LPN | B40: {=_xlfn.XLOOKUP(A40,'P&L Trending Data'!A41:A181,'P&L Trending Data'!B41:Y181)} -> 7758 | C40: 3.02 | D40: 1974 | E40: 0.82 | F40: 3687 | G40: 1.42 | H40: 0 | I40: 0 | J40: 1264 | K40: 0.51 | L40: 193 | M40: 0.08 | N40: 882 | O40: 0.37 | P40: 0 | Q40: 0 | R40: 0 | S40: 0 | T40: 260 | U40: 0.11 | V40: 0 | W40: 0 | X40: 2399 | Y40: 0.98 | Z40: =B40+D40+F40+H40+J40+L40+N40+P40+R40+T40+V40+X40 -> 18417 | AA40: =C40+E40+G40+I40+K40+M40+O40+Q40+S40+U40+W40+Y40 -> 7.31
A41: Contract Aides & Orderlies | B41: {=_xlfn.XLOOKUP(A41,'P&L Trending Data'!A42:A182,'P&L Trending Data'!B42:Y182)} -> 17567 | C41: 6.85 | D41: 28226 | E41: 11.76 | F41: 33572 | G41: 12.95 | H41: 11167 | I41: 4.96 | J41: 10005 | K41: 4.06 | L41: 7191 | M41: 3.11 | N41: 4771 | O41: 2.01 | P41: 3121 | Q41: 1.34 | R41: 24585 | S41: 9.99 | T41: 11843 | U41: 5.22 | V41: 3955 | W41: 1.84 | X41: 11865 | Y41: 4.84 | Z41: =B41+D41+F41+H41+J41+L41+N41+P41+R41+T41+V41+X41 -> 167868 | AA41: =C41+E41+G41+I41+K41+M41+O41+Q41+S41+U41+W41+Y41 -> 68.93
A42: Medical Supplies | B42: {=_xlfn.XLOOKUP(A42,'P&L Trending Data'!A43:A183,'P&L Trending Data'!B43:Y183)} -> 9096 | C42: 3.54 | D42: 8183 | E42: 3.41 | F42: 11766 | G42: 4.54 | H42: 8005 | I42: 3.55 | J42: 9016 | K42: 3.66 | L42: 7306 | M42: 3.16 | N42: 8808 | O42: 3.71 | P42: 7412 | Q42: 3.17 | R42: 10819 | S42: 4.39 | T42: 8067 | U42: 3.56 | V42: 8778 | W42: 4.09 | X42: 10387 | Y42: 4.24 | Z42: =B42+D42+F42+H42+J42+L42+N42+P42+R42+T42+V42+X42 -> 107643 | AA42: =C42+E42+G42+I42+K42+M42+O42+Q42+S42+U42+W42+Y42 -> 45.02
...

Sheet PR Detail Trending
A1: =BS!A1 -> Allure of Peru
A2: Payroll Summary Detail Trending
A3: ='PR Trending Data'!B3 -> 1/1/2025 to 12/31/2025
B5: ='P&L Detail Trending'!B5 -> 45658 | D5: =EDATE(B5,1) -> 45689 | F5: =EDATE(D5,1) -> 45717 | H5: =EDATE(F5,1) -> 45748 | J5: =EDATE(H5,1) -> 45778 | L5: =EDATE(J5,1) -> 45809 | N5: =EDATE(L5,1) -> 45839 | P5: =EDATE(N5,1) -> 45870 | R5: =EDATE(P5,1) -> 45901 | T5: =EDATE(R5,1) -> 45931 | V5: =EDATE(T5,1) -> 45962 | X5: =EDATE(V5,1) -> 45992 | Z5: TOTALS
B6: Actual $ | C6: Actual / Day | D6: Actual $ | E6: Actual / Day | F6: Actual $ | G6: Actual / Day | H6: Actual $ | I6: Actual / Day | J6: Actual $ | K6: Actual / Day | L6: Actual $ | M6: Actual / Day | N6: Actual $ | O6: Actual / Day | P6: Actual $ | Q6: Actual / Day | R6: Actual $ | S6: Actual / Day | T6: Actual $ | U6: Actual / Day | V6: Actual $ | W6: Actual / Day | X6: Actual $ | Y6: Actual / Day | Z6: Actual $ | AA6: Actual / Day
A7: Payroll Summary
A8: P/R Administrator | B8: {=_xlfn.XLOOKUP(A8,'PR Trending Data'!A9:A74,'PR Trending Data'!B9:Y74)} -> 10221 | C8: 3.98 | D8: 9232 | E8: 3.85 | F8: 10241 | G8: 3.95 | H8: 10188 | I8: 4.52 | J8: 10528 | K8: 4.27 | L8: 10188 | M8: 4.41 | N8: 10528 | O8: 4.43 | P8: 10528 | Q8: 4.5 | R8: 10188 | S8: 4.14 | T8: 10528 | U8: 4.64 | V8: 10188 | W8: 4.75 | X8: 11658 | Y8: 4.76 | Z8: =B8+D8+F8+H8+J8+L8+N8+P8+R8+T8+V8+X8 -> 124216 | AA8: =C8+E8+G8+I8+K8+M8+O8+Q8+S8+U8+W8+Y8 -> 52.2
A9: P/R Administrator Covid | B9: {=_xlfn.XLOOKUP(A9,'PR Trending Data'!A10:A75,'PR Trending Data'!B10:Y75)} -> 1922 | C9: 0.75 | D9: 1487 | E9: 0.62 | F9: 113 | G9: 0.04 | H9: 2287 | I9: 1.02 | J9: 1608 | K9: 0.65 | L9: 1871 | M9: 0.81 | N9: 1014 | O9: 0.43 | P9: 1741 | Q9: 0.74 | R9: 303 | S9: 0.12 | T9: 1606 | U9: 0.71 | V9: 659 | W9: 0.31 | X9: 0 | Y9: 0 | Z9: =B9+D9+F9+H9+J9+L9+N9+P9+R9+T9+V9+X9 -> 14611 | AA9: =C9+E9+G9+I9+K9+M9+O9+Q9+S9+U9+W9+Y9 -> 6.2
A10: P/R Assistant Admin Covid | B10: {=_xlfn.XLOOKUP(A10,'PR Trending Data'!A11:A76,'PR Trending Data'!B11:Y76)} -> 0 | C10: 0 | D10: 0 | E10: 0 | F10: 0 | G10: 0 | H10: 0 | I10: 0 | J10: 0 | K10: 0 | L10: 0 | M10: 0 | N10: 0 | O10: 0 | P10: 0 | Q10: 0 | R10: 0 | S10: 0 | T10: 0 | U10: 0 | V10: 0 | W10: 0 | X10: 0 | Y10: 0 | Z10: =B10+D10+F10+H10+J10+L10+N10+P10+R10+T10+V10+X10 -> 0 | AA10: =C10+E10+G10+I10+K10+M10+O10+Q10+S10+U10+W10+Y10 -> 0
A11: P/R Assistant Administrator | B11: {=_xlfn.XLOOKUP(A11,'PR Trending Data'!A12:A77,'PR Trending Data'!B12:Y77)} -> 0 | C11: 0 | D11: 0 | E11: 0 | F11: 0 | G11: 0 | H11: 0 | I11: 0 | J11: 0 | K11: 0 | L11: 0 | M11: 0 | N11: 0 | O11: 0 | P11: 0 | Q11: 0 | R11: 0 | S11: 0 | T11: 0 | U11: 0 | V11: 0 | W11: 0 | X11: 0 | Y11: 0 | Z11: =B11+D11+F11+H11+J11+L11+N11+P11+R11+T11+V11+X11 -> 0 | AA11: =C11+E11+G11+I11+K11+M11+O11+Q11+S11+U11+W11+Y11 -> 0
A12: P/R DON | B12: {=_xlfn.XLOOKUP(A12,'PR Trending Data'!A13:A78,'PR Trending Data'!B13:Y78)} -> 9212 | C12: 3.59 | D12: 7717 | E12: 3.21 | F12: 8952 | G12: 3.45 | H12: 8492 | I12: 3.77 | J12: 8997 | K12: 3.65 | L12: 8509 | M12: 3.68 | N12: 8817 | O12: 3.71 | P12: 8597 | Q12: 3.68 | R12: 8438 | S12: 3.43 | T12: 8719 | U12: 3.84 | V12: 8626 | W12: 4.02 | X12: 8871 | Y12: 3.62 | Z12: =B12+D12+F12+H12+J12+L12+N12+P12+R12+T12+V12+X12 -> 103947 | AA12: =C12+E12+G12+I12+K12+M12+O12+Q12+S12+U12+W12+Y12 -> 43.65
A13: P/R DON Covid | B13: {=_xlfn.XLOOKUP(A13,'PR Trending Data'!A14:A79,'PR Trending Data'!B14:Y79)} -> 0 | C13: 0 | D13: 0 | E13: 0 | F13: 0 | G13: 0 | H13: 0 | I13: 0 | J13: 0 | K13: 0 | L13: 0 | M13: 0 | N13: 1250 | O13: 0.53 | P13: 0 | Q13: 0 | R13: 0 | S13: 0 | T13: 321 | U13: 0.14 | V13: 429 | W13: 0.2 | X13: 0 | Y13: 0 | Z13: =B13+D13+F13+H13+J13+L13+N13+P13+R13+T13+V13+X13 -> 2000 | AA13: =C13+E13+G13+I13+K13+M13+O13+Q13+S13+U13+W13+Y13 -> 0.87
A14: P/R ADON | B14: {=_xlfn.XLOOKUP(A14,'PR Trending Data'!A15:A80,'PR Trending Data'!B15:Y80)} -> 7877 | C14: 3.07 | D14: 7354 | E14: 3.06 | F14: 7832 | G14: 3.02 | H14: 7552 | I14: 3.35 | J14: 8298 | K14: 3.36 | L14: 7532 | M14: 3.26 | N14: 7601 | O14: 3.2 | P14: 7638 | Q14: 3.27 | R14: 6659 | S14: 2.7 | T14: 1904 | U14: 0.84 | V14: 6738 | W14: 3.14 | X14: 8630 | Y14: 3.52 | Z14: =B14+D14+F14+H14+J14+L14+N14+P14+R14+T14+V14+X14 -> 85615 | AA14: =C14+E14+G14+I14+K14+M14+O14+Q14+S14+U14+W14+Y14 -> 35.79
A15: P/R ADON Covid | B15: {=_xlfn.XLOOKUP(A15,'PR Trending Data'!A16:A81,'PR Trending Data'!B16:Y81)} -> 0 | C15: 0 | D15: 0 | E15: 0 | F15: 0 | G15: 0 | H15: 0 | I15: 0 | J15: 0 | K15: 0 | L15: 0 | M15: 0 | N15: 0 | O15: 0 | P15: 0 | Q15: 0 | R15: 0 | S15: 0 | T15: 0 | U15: 0 | V15: 0 | W15: 0 | X15: 0 | Y15: 0 | Z15: =B15+D15+F15+H15+J15+L15+N15+P15+R15+T15+V15+X15 -> 0 | AA15: =C15+E15+G15+I15+K15+M15+O15+Q15+S15+U15+W15+Y15 -> 0
A16: P/R RN | B16: {=_xlfn.XLOOKUP(A16,'PR Trending Data'!A17:A82,'PR Trending Data'!B17:Y82)} -> 65236 | C16: 25.42 | D16: 60365 | E16: 25.14 | F16: 68632 | G16: 26.47 | H16: 69671 | I16: 30.92 | J16: 71475 | K16: 28.98 | L16: 69227 | M16: 29.97 | N16: 72869 | O16: 30.68 | P16: 66824 | Q16: 28.59 | R16: 64087 | S16: 26.03 | T16: 66427 | U16: 29.29 | V16: 64275 | W16: 29.97 | X16: 61682 | Y16: 25.17 | Z16: =B16+D16+F16+H16+J16+L16+N16+P16+R16+T16+V16+X16 -> 800770 | AA16: =C16+E16+G16+I16+K16+M16+O16+Q16+S16+U16+W16+Y16 -> 336.63
A17: P/R RN Covid | B17: {=_xlfn.XLOOKUP(A17,'PR Trending Data'!A18:A83,'PR Trending Data'!B18:Y83)} -> 0 | C17: 0 | D17: 0 | E17: 0 | F17: 0 | G17: 0 | H17: 0 | I17: 0 | J17: 0 | K17: 0 | L17: 0 | M17: 0 | N17: 0 | O17: 0 | P17: 0 | Q17: 0 | R17: 0 | S17: 0 | T17: 0 | U17: 0 | V17: 0 | W17: 0 | X17: 0 | Y17: 0 | Z17: =B17+D17+F17+H17+J17+L17+N17+P17+R17+T17+V17+X17 -> 0 | AA17: =C17+E17+G17+I17+K17+M17+O17+Q17+S17+U17+W17+Y17 -> 0
A18: P/R LPN | B18: {=_xlfn.XLOOKUP(A18,'PR Trending Data'!A19:A84,'PR Trending Data'!B19:Y84)} -> 0 | C18: 0 | D18: 0 | E18: 0 | F18: 0 | G18: 0 | H18: 0 | I18: 0 | J18: 0 | K18: 0 | L18: 12970 | M18: 5.61 | N18: -12970 | O18: -5.46 | P18: 0 | Q18: 0 | R18: 0 | S18: 0 | T18: 0 | U18: 0 | V18: 0 | W18: 0 | X18: 0 | Y18: 0 | Z18: =B18+D18+F18+H18+J18+L18+N18+P18+R18+T18+V18+X18 -> 0 | AA18: =C18+E18+G18+I18+K18+M18+O18+Q18+S18+U18+W18+Y18 -> 0.15
A19: P/R LPN Covid | B19: {=_xlfn.XLOOKUP(A19,'PR Trending Data'!A20:A85,'PR Trending Data'!B20:Y85)} -> 36740 | C19: 14.32 | D19: 36131 | E19: 15.05 | F19: 35983 | G19: 13.88 | H19: 33791 | I19: 15 | J19: 33989 | K19: 13.78 | L19: 27241 | M19: 11.79 | N19: 47661 | O19: 20.07 | P19: 34825 | Q19: 14.9 | R19: 35716 | S19: 14.51 | T19: 40897 | U19: 18.03 | V19: 39372 | W19: 18.36 | X19: 40479 | Y19: 16.52 | Z19: =B19+D19+F19+H19+J19+L19+N19+P19+R19+T19+V19+X19 -> 442825 | AA19: =C19+E19+G19+I19+K19+M19+O19+Q19+S19+U19+W19+Y19 -> 186.21
... A47: P/R Admissions Covid | B47: {=_xlfn.XLOOKUP(A47,'PR Trending Data'!A48:A113,'PR Trending Data'!B48:Y113)} -> 0 | C47: 0 | D47: 0 | E47: 0 | F47: 0 | G47: 0 | H47: 0 | I47: 0 | J47: 0 | K47: 0 | L47: 0 | M47: 0 | N47: 0 | O47: 0 | P47: 0 | Q47: 0 | R47: 0 | S47: 0 | T47: 0 | U47: 0 | V47: 0 | W47: 0 | X47: 0 | Y47: 0 | Z47: =B47+D47+F47+H47+J47+L47+N47+P47+R47+T47+V47+X47 -> 0 | AA47: =C47+E47+G47+I47+K47+M47+O47+Q47+S47+U47+W47+Y47 -> 0
A48: TOTAL Payroll Summary | B48: {=_xlfn.XLOOKUP(A48,'PR Trending Data'!A49:A114,'PR Trending Data'!B49:Y114)} -> 379332 | C48: 147.83 | D48: 332103 | E48: 138.32 | F48: 390919 | G48: 150.76 | H48: 373220 | I48: 165.65 | J48: 401243 | K48: 162.71 | L48: 412670 | M48: 178.65 | N48: 386222 | O48: 162.62 | P48: 365887 | Q48: 156.56 | R48: 378054 | S48: 153.56 | T48: 370281 | U48: 163.26 | V48: 373009 | W48: 173.9 | X48: 401772 | Y48: 163.92 | Z48: =SUM(Z8:Z47) -> 4564722 | AA48: =SUM(AA8:AA47) -> 1917.7
A49: Payroll Taxes Detail | B49: {=_xlfn.XLOOKUP(A49,'PR Trending Data'!A50:A115,'PR Trending Data'!B50:Y115)} -> 0 | C49: 0 | D49: 0 | E49: 0 | F49: 0 | G49: 0 | H49: 0 | I49: 0 | J49: 0 | K49: 0 | L49: 0 | M49: 0 | N49: 0 | O49: 0 | P49: 0 | Q49: 0 | R49: 0 | S49: 0 | T49: 0 | U49: 0 | V49: 0 | W49: 0 | X49: 0 | Y49: 0
A50: FICA | B50: {=_xlfn.XLOOKUP(A50,'PR Trending Data'!A51:A116,'PR Trending Data'!B51:Y116)} -> 28146 | C50: 10.97 | D50: 24576 | E50: 10.24 | F50: 27649 | G50: 10.66 | H50: 27609 | I50: 12.25 | J50: 29751 | K50: 12.06 | L50: 29195 | M50: 12.64 | N50: 28527 | O50: 12.01 | P50: 27223 | Q50: 11.65 | R50: 27430 | S50: 11.14 | T50: 22786 | U50: 10.05 | V50: 27048 | W50: 12.61 | X50: 28986 | Y50: 11.83 | Z50: =B50+D50+F50+H50+J50+L50+N50+P50+R50+T50+V50+X50 -> 328926 | AA50: =C50+E50+G50+I50+K50+M50+O50+Q50+S50+U50+W50+Y50 -> 138.11
A51: State Unemployment | B51: {=_xlfn.XLOOKUP(A51,'PR Trending Data'!A52:A117,'PR Trending Data'!B52:Y117)} -> 13556 | C51: 5.28 | D51: 10269 | E51: 4.28 | F51: 8818 | G51: 3.4 | H51: 6179 | I51: 2.74 | J51: 5508 | K51: 2.23 | L51: 3839 | M51: 1.66 | N51: 2743 | O51: 1.16 | P51: 2164 | Q51: 0.93 | R51: 2174 | S51: 0.88 | T51: 2092 | U51: 0.92 | V51: 1895 | W51: 0.88 | X51: 2237 | Y51: 0.91 | Z51: =B51+D51+F51+H51+J51+L51+N51+P51+R51+T51+V51+X51 -> 61474 | AA51: =C51+E51+G51+I51+K51+M51+O51+Q51+S51+U51+W51+Y51 -> 25.27
A52: Federal Unemployment | B52: {=_xlfn.XLOOKUP(A52,'PR Trending Data'!A53:A118,'PR Trending Data'!B53:Y118)} -> 1959 | C52: 0.76 | D52: 924 | E52: 0.38 | F52: 496 | G52: 0.19 | H52: 341 | I52: 0.15 | J52: 363 | K52: 0.15 | L52: 315 | M52: 0.14 | N52: 261 | O52: 0.11 | P52: 172 | Q52: 0.07 | R52: 134 | S52: 0.05 | T52: 150 | U52: 0.07 | V52: 184 | W52: 0.09 | X52: 961 | Y52: 0.39 | Z52: =B52+D52+F52+H52+J52+L52+N52+P52+R52+T52+V52+X52 -> 6260 | AA52: =C52+E52+G52+I52+K52+M52+O52+Q52+S52+U52+W52+Y52 -> 2.55
A53: Payroll Taxes - Other | B53: {=_xlfn.XLOOKUP(A53,'PR Trending Data'!A54:A119,'PR Trending Data'!B54:Y119)} -> 0 | C53: 0 | D53: 0 | E53: 0 | F53: 0 | G53: 0 | H53: 0 | I53: 0 | J53: 0 | K53: 0 | L53: 0 | M53: 0 | N53: 0 | O53: 0 | P53: 0 | Q53: 0 | R53: 0 | S53: 0 | T53: 0 | U53: 0 | V53: 0 | W53: 0 | X53: 0 | Y53: 0 | Z53: =B53+D53+F53+H53+J53+L53+N53+P53+R53+T53+V53+X53 -> 0 | AA53: =C53+E53+G53+I53+K53+M53+O53+Q53+S53+U53+W53+Y53 -> 0
A54: TOTAL Payroll Taxes Detail | B54: {=_xlfn.XLOOKUP(A54,'PR Trending Data'!A55:A120,'PR Trending Data'!B55:Y120)} -> 43661 | C54: 17.02 | D54: 35768 | E54: 14.9 | F54: 36963 | G54: 14.25 | H54: 34129 | I54: 15.15 | J54: 35621 | K54: 14.44 | L54: 33348 | M54: 14.44 | N54: 31531 | O54: 13.28 | P54: 29560 | Q54: 12.65 | R54: 29738 | S54: 12.08 | T54: 25028 | U54: 11.04 | V54: 29128 | W54: 13.58 | X54: 32183 | Y54: 13.13 | Z54: =SUM(Z50:Z53) -> 396660 | AA54: =SUM(AA50:AA53) -> 165.93
A55: Total Payroll | B55: {=_xlfn.XLOOKUP(A55,'PR Trending Data'!A56:A121,'PR Trending Data'!B56:Y121)} -> 422993 | C55: 164.85 | D55: 367871 | E55: 153.22 | F55: 427882 | G55: 165.01 | H55: 407349 | I55: 180.8 | J55: 436864 | K55: 177.15 | L55: 446019 | M55: 193.08 | N55: 417754 | O55: 175.9 | P55: 395447 | Q55: 169.21 | R55: 407792 | S55: 165.63 | T55: 395309 | U55: 174.3 | V55: 402137 | W55: 187.48 | X55: 433956 | Y55: 177.05 | Z55: =+Z54+Z48 -> 4961382 | AA55: =+AA54+AA48 -> 2083.63
A56: Agency Detail | B56: {=_xlfn.XLOOKUP(A56,'PR Trending Data'!A57:A122,'PR Trending Data'!B57:Y122)} -> 0 | C56: 0 | D56: 0 | E56: 0 | F56: 0 | G56: 0 | H56: 0 | I56: 0 | J56: 0 | K56: 0 | L56: 0 | M56: 0 | N56: 0 | O56: 0 | P56: 0 | Q56: 0 | R56: 0 | S56: 0 | T56: 0 | U56: 0 | V56: 0 | W56: 0 | X56: 0 | Y56: 0
A57: Agency Salaries - RN | B57: {=_xlfn.XLOOKUP(A57,'PR Trending Data'!A58:A123,'PR Trending Data'!B58:Y123)} -> 15000 | C57: 5.85 | D57: 2529 | E57: 1.05 | F57: 5652 | G57: 2.18 | H57: 2333 | I57: 1.04 | J57: 8661 | K57: 3.51 | L57: 3684 | M57: 1.59 | N57: 2170 | O57: 0.91 | P57: 2527 | Q57: 1.08 | R57: 14053 | S57: 5.71 | T57: 12299 | U57: 5.42 | V57: 0 | W57: 0 | X57: 8315 | Y57: 3.39 | Z57: =B57+D57+F57+H57+J57+L57+N57+P57+R57+T57+V57+X57 -> 77223 | AA57: =C57+E57+G57+I57+K57+M57+O57+Q57+S57+U57+W57+Y57 -> 31.73
A58: Covid Agency Salaries - RN | B58: {=_xlfn.XLOOKUP(A58,'PR Trending Data'!A59:A124,'PR Trending Data'!B59:Y124)} -> 2683 | C58: 1.05 | D58: 2226 | E58: 0.93 | F58: 0 | G58: 0 | H58: 95 | I58: 0.04 | J58: 0 | K58: 0 | L58: 0 | M58: 0 | N58: 0 | O58: 0 | P58: 0 | Q58: 0 | R58: 0 | S58: 0 | T58: 0 | U58: 0 | V58: 0 | W58: 0 | X58: 0 | Y58: 0 | Z58: =B58+D58+F58+H58+J58+L58+N58+P58+R58+T58+V58+X58 -> 5004 | AA58: =C58+E58+G58+I58+K58+M58+O58+Q58+S58+U58+W58+Y58 -> 2.02
A59: Agency Salaries - LPN | B59: {=_xlfn.XLOOKUP(A59,'PR Trending Data'!A60:A125,'PR Trending Data'!B60:Y125)} -> 7758 | C59: 3.02 | D59: 1974 | E59: 0.82 | F59: 3687 | G59: 1.42 | H59: 0 | I59: 0 | J59: 1264 | K59: 0.51 | L59: 193 | M59: 0.08 | N59: 882 | O59: 0.37 | P59: 0 | Q59: 0 | R59: 0 | S59: 0 | T59: 260 | U59: 0.11 | V59: 0 | W59: 0 | X59: 2399 | Y59: 0.98 | Z59: =B59+D59+F59+H59+J59+L59+N59+P59+R59+T59+V59+X59 -> 18417 | AA59: =C59+E59+G59+I59+K59+M59+O59+Q59+S59+U59+W59+Y59 -> 7.31
A60: Covid Agency Salaries - LPN | B60: {=_xlfn.XLOOKUP(A60,'PR Trending Data'!A61:A126,'PR Trending Data'!B61:Y126)} -> 0 | C60: 0 | D60: 0 | E60: 0 | F60: 0 | G60: 0 | H60: 0 | I60: 0 | J60: 0 | K60: 0 | L60: 0 | M60: 0 | N60: 0 | O60: 0 | P60: 0 | Q60: 0 | R60: 0 | S60: 0 | T60: 0 | U60: 0 | V60: 0 | W60: 0 | X60: 0 | Y60: 0 | Z60: =B60+D60+F60+H60+J60+L60+N60+P60+R60+T60+V60+X60 -> 0 | AA60: =C60+E60+G60+I60+K60+M60+O60+Q60+S60+U60+W60+Y60 -> 0
A61: Agency Salaries - CNA | B61: {=_xlfn.XLOOKUP(A61,'PR Trending Data'!A62:A127,'PR Trending Data'!B62:Y127)} -> 17063 | C61: 6.65 | D61: 18864 | E61: 7.86 | F61: 32475 | G61: 12.52 | H61: 10108 | I61: 4.49 | J61: 9671 | K61: 3.92 | L61: 7191 | M61: 3.11 | N61: 2546 | O61: 1.07 | P61: 2770 | Q61: 1.19 | R61: 21952 | S61: 8.92 | T61: 11843 | U61: 5.22 | V61: 2491 | W61: 1.16 | X61: 8728 | Y61: 3.56 | Z61: =B61+D61+F61+H61+J61+L61+N61+P61+R61+T61+V61+X61 -> 145702 | AA61: =C61+E61+G61+I61+K61+M61+O61+Q61+S61+U61+W61+Y61 -> 59.67
A62: Covid Agency Salaries - CNA | B62: {=_xlfn.XLOOKUP(A62,'PR Trending Data'!A63:A128,'PR Trending Data'!B63:Y128)} -> 504 | C62: 0.2 | D62: 8450 | E62: 3.52 | F62: 0 | G62: 0 | H62: 0 | I62: 0 | J62: 0 | K62: 0 | L62: 0 | M62: 0 | N62: 0 | O62: 0 | P62: 0 | Q62: 0 | R62: 0 | S62: 0 | T62: 0 | U62: 0 | V62: 0 | W62: 0 | X62: 0 | Y62: 0 | Z62: =B62+D62+F62+H62+J62+L62+N62+P62+R62+T62+V62+X62 -> 8954 | AA62: =C62+E62+G62+I62+K62+M62+O62+Q62+S62+U62+W62+Y62 -> 3.72
A63: TOTAL Agency Detail | B63: {=_xlfn.XLOOKUP(A63,'PR Trending Data'!A64:A129,'PR Trending Data'!B64:Y129)} -> 43008 | C63: 16.76 | D63: 34044 | E63: 14.18 | F63: 41815 | G63: 16.13 | H63: 12536 | I63: 5.56 | J63: 19596 | K63: 7.95 | L63: 11068 | M63: 4.79 | N63: 5598 | O63: 2.36 | P63: 5297 | Q63: 2.27 | R63: 36004 | S63: 14.62 | T63: 24402 | U63: 10.76 | V63: 2491 | W63: 1.16 | X63: 19442 | Y63: 7.93 | Z63: =SUM(Z57:Z62) -> 255300 | AA63: =SUM(AA57:AA62) -> 104.45
A64: Empire Detail | B64: {=_xlfn.XLOOKUP(A64,'PR Trending Data'!A65:A130,'PR Trending Data'!B65:Y130)} -> 0 | C64: 0 | D64: 0 | E64: 0 | F64: 0 | G64: 0 | H64: 0 | I64: 0 | J64: 0 | K64: 0 | L64: 0 | M64: 0 | N64: 0 | O64: 0 | P64: 0 | Q64: 0 | R64: 0 | S64: 0 | T64: 0 | U64: 0 | V64: 0 | W64: 0 | X64: 0 | Y64: 0
A65: Empire Staffing Salaries RN | B65: {=_xlfn.XLOOKUP(A65,'PR Trending Data'!A66:A131,'PR Trending Data'!B66:Y131)} -> 7307 | C65: 2.85 | D65: 5276 | E65: 2.2 | F65: 9591 | G65: 3.7 | H65: 2102 | I65: 0.93 | J65: 6920 | K65: 2.81 | L65: 10029 | M65: 4.34 | N65: 11586 | O65: 4.88 | P65: 3266 | Q65: 1.4 | R65: 12835 | S65: 5.21 | T65: 0 | U65: 0 | V65: 8223 | W65: 3.83 | X65: 18329 | Y65: 7.48 | Z65: =B65+D65+F65+H65+J65+L65+N65+P65+R65+T65+V65+X65 -> 95464 | AA65: =C65+E65+G65+I65+K65+M65+O65+Q65+S65+U65+W65+Y65 -> 39.63
A66: Empire Staffing Salaries LPN | B66: {=_xlfn.XLOOKUP(A66,'PR Trending Data'!A67:A132,'PR Trending Data'!B67:Y132)} -> 0 | C66: 0 | D66: 0 | E66: 0 | F66: 0 | G66: 0 | H66: 0 | I66: 0 | J66: 0 | K66: 0 | L66: 0 | M66: 0 | N66: 0 | O66: 0 | P66: 0 | Q66: 0 | R66: 0 | S66: 0 | T66: 0 | U66: 0 | V66: 0 | W66: 0 | X66: 0 | Y66: 0 | Z66: =B66+D66+F66+H66+J66+L66+N66+P66+R66+T66+V66+X66 -> 0 | AA66: =C66+E66+G66+I66+K66+M66+O66+Q66+S66+U66+W66+Y66 -> 0
A67: Empire Staffing Salaries CNA | B67: {=_xlfn.XLOOKUP(A67,'PR Trending Data'!A68:A133,'PR Trending Data'!B68:Y133)} -> 0 | C67: 0 | D67: 912 | E67: 0.38 | F67: 1097 | G67: 0.42 | H67: 1059 | I67: 0.47 | J67: 335 | K67: 0.14 | L67: 0 | M67: 0 | N67: 2224 | O67: 0.94 | P67: 351 | Q67: 0.15 | R67: 2633 | S67: 1.07 | T67: 0 | U67: 0 | V67: 1464 | W67: 0.68 | X67: 3137 | Y67: 1.28 | Z67: =B67+D67+F67+H67+J67+L67+N67+P67+R67+T67+V67+X67 -> 13212 | AA67: =C67+E67+G67+I67+K67+M67+O67+Q67+S67+U67+W67+Y67 -> 5.53
A68: TOTAL Empire Detail | B68: {=_xlfn.XLOOKUP(A68,'PR Trending Data'!A69:A134,'PR Trending Data'!B69:Y134)} -> 7307 | C68: 2.85 | D68: 6188 | E68: 2.58 | F68: 10688 | G68: 4.12 | H68: 3161 | I68: 1.4 | J68: 7255 | K68: 2.94 | L68: 10029 | M68: 4.34 | N68: 13810 | O68: 5.81 | P68: 3618 | Q68: 1.55 | R68: 15468 | S68: 6.28 | T68: 0 | U68: 0 | V68: 9687 | W68: 4.52 | X68: 21466 | Y68: 8.76 | Z68: =SUM(Z65:Z67) -> 108676 | AA68: =SUM(AA65:AA67) -> 45.16
...

Sheet BS Data
A1: ?"Date: May 8 | B1: 2026" | C1: Allure of Peru | D1: Facility #IL6004303
A2: Time: 12:07:07 EDT | B2: Balance Sheet Analysis
A3: User: Roth - Tracy Morkunas | B3: As Of 12/31/2025
A5: Include Adjustment Periods: NO | B5: Include Closing Periods: NO
B7: CURRENT PERIOD_Actual $
A8: Current Assets
A9: Cash | B9: 22699
A10: Accounts Receivable | B10: 1715902
A11: Allowance for Doubtful Account | B11: -50489
A12: Prepaid Expense | B12: 156097
A13: Intercompany Receivable | B13: -611166
A14: Other Current Assets | B14: 1783
A15: TOTAL Current Assets | B15: 1234827
A16: Fixed Assets
A17: Building and Land | B17: 3416
A18: Equipment | B18: 131927
A19: Furniture and Fixtures | B19: 4749
A20: Leasehold Improvements | B20: 685794
A21: CIP - Leasehold Improvements | B21: 0
A22: Vehicles | B22: 1099
A23: Organization Costs | B23: 23124
A24: Loan Costs | B24: 0
A25: Less Accumulated Depreciation | B25: -180889
A26: Replacement Reserve | B26: 31590
A27: TOTAL Fixed Assets | B27: 700810
A28: Total Assets | B28: 1935637
A29: Current Liabilities
A30: Accounts Payable | B30: 782460
A31: Credit Card Payable | B31: 0
A32: Accrued Expenses | B32: 231834
A33: Accrued Payroll | B33: 116658
A34: Accrued Benefits | B34: 0
A35: Payroll Liabilites | B35: 0
A36: Line of Credit | B36: 850000
A37: Other Current Liabilities | B37: 1446
A38: Resident Security Deposits | B38: 0
A39: TOTAL Current Liabilities | B39: 1982397
A40: Long Term Liabilities | B40: 0
A41: TOTAL Liabilities | B41: 1982397
A42: Equity
...

Sheet P&L Data
A1: ?"Date: May 8 | B1: 2026" | C1: Allure of Peru | D1: Facility #IL6004303
A2: Time: 12:08:08 EDT | B2: Income Statement Detail
A3: User: Roth - Tracy Morkunas | B3: 1/1/2025 to 12/31/2025
A5: Include Adjustment Periods: NO | B5: Include Closing Periods: NO
B7: CURRENT PERIOD_Actual $ | C7: CURRENT PERIOD_Actual / Day | D7: YEAR TO DATE_Actual $ | E7: YEAR TO DATE_Actual / Day
A8: Revenue
A9: Medicaid | B9: 4650290 | C9: 279.75 | D9: 4650290 | E9: 279.75
A10: Hospice | B10: 404354 | C10: 278.29 | D10: 404354 | E10: 278.29
A11: Medicare A | B11: 2480638 | C11: 682.43 | D11: 2480638 | E11: 682.43
A12: Commercial Insurance | B12: 924175 | C12: 458.65 | D12: 924175 | E12: 458.65
A13: Private Pay | B13: 1446974 | C13: 295.24 | D13: 1446974 | E13: 295.24
A14: Veteran Affairs | B14: 0 | D14: 0
A15: Medicare / Managed Care B | B15: 297113 | D15: 297113
A16: Private Pay Independent Living | B16: 0 | D16: 0
A17: Home Care Income | B17: 0 | D17: 0
A18: Daily Training Program | B18: 0 | D18: 0
A19: Other | B19: 5276 | D19: 5276
A20: Stimulus Income | B20: 0 | D20: 0
A21: Incentive Payments | B21: 215428 | C21: 7.53 | D21: 215428 | E21: 7.53
A22: TOTAL Revenue | B22: 10424247 | C22: 364.14 | D22: 10424247 | E22: 364.14
A23: Patient Days
A24: Medicaid | B24: 16663 | D24: 16663
A25: Hospice | B25: 1453 | D25: 1453
A26: Medicare A | B26: 3635 | D26: 3635
A27: Commercial Insurance | B27: 2015 | D27: 2015
A28: Private Pay | B28: 4894 | D28: 4894
A29: Veteran Affairs | B29: 0 | D29: 0
A30: Independent Living | B30: 0 | D30: 0
A31: TOTAL Patient Days | B31: 28660 | D31: 28660
B32: 0 | D32: 0
A33: Nursing & Medical
A34: Director Of Nursing | B34: 105946 | C34: 3.7 | D34: 105946 | E34: 3.7
A35: Assistant Director Of Nursing | B35: 85613 | C35: 2.99 | D35: 85613 | E35: 2.99
A36: Payroll RN | B36: 800771 | C36: 27.97 | D36: 800771 | E36: 27.97
A37: Payroll LPN | B37: 442824 | C37: 15.47 | D37: 442824 | E37: 15.47
A38: Payroll Aides & Orderlies | B38: 1861774 | C38: 65.04 | D38: 1861774 | E38: 65.04
A39: Payroll Nursing Clerical | B39: 92496 | C39: 3.23 | D39: 92496 | E39: 3.23
A40: Payroll Medical Records | B40: 0 | C40: 0 | D40: 0 | E40: 0
A41: Contract RN | B41: 177691 | C41: 6.21 | D41: 177691 | E41: 6.21
A42: Contract LPN | B42: 18418 | C42: 0.64 | D42: 18418 | E42: 0.64
...

Sheet P&L Trending Data
A1: ?"Date: May 8 | B1: 2026" | C1: Allure of Peru | D1: Facility #IL6004303
A2: Time: 12:08:42 EDT | B2: Income Statement Trending Detail - GGM
A3: User: Roth - Tracy Morkunas
B4: 1/1/2025 to 12/31/2025
A6: Include Adjustment Periods: NO | B6: Include Closing Periods: NO
B8: January 25_Actual $ | C8: January 25_Actual / Day | D8: February 25_Actual $ | E8: February 25_Actual / Day | F8: March 25_Actual $ | G8: March 25_Actual / Day | H8: April 25_Actual $ | I8: April 25_Actual / Day | J8: May 25_Actual $ | K8: May 25_Actual / Day | L8: June 25_Actual $ | M8: June 25_Actual / Day | N8: July 25_Actual $ | O8: July 25_Actual / Day | P8: August 25_Actual $ | Q8: August 25_Actual / Day | R8: September 25_Actual $ | S8: September 25_Actual / Day | T8: October 25_Actual $ | U8: October 25_Actual / Day | V8: November 25_Actual $ | W8: November 25_Actual / Day | X8: December 25_Actual $ | Y8: December 25_Actual / Day | Z8: TOTALS_Actual $ | AA8: TOTALS_Actual / Day
A9: Revenue
A10: Medicaid | B10: 388276 | C10: 276.75 | D10: 408258 | E10: 279.82 | F10: 406113 | G10: 278.35 | H10: 370960 | I10: 282.53 | J10: 371972 | K10: 282.87 | L10: 407087 | M10: 282.11 | N10: 395127 | O10: 295.98 | P10: 413088 | Q10: 295.7 | R10: 410913 | S10: 296.05 | T10: 369135 | U10: 262.73 | V10: 320350 | W10: 261.3 | X10: 389012 | Y10: 262.85 | Z10: 4650290 | AA10: 279.75
A11: Hospice | B11: 23801 | C11: 276.76 | D11: 26023 | E11: 279.82 | F11: 33402 | G11: 278.35 | H11: 32504 | I11: 282.64 | J11: 37308 | K11: 282.64 | L11: 18649 | M11: 286.91 | N11: 27562 | O11: 296.37 | P11: 41492 | Q11: 296.37 | R11: 42085 | S11: 296.37 | T11: 37000 | U11: 262.41 | V11: 30470 | W11: 253.92 | X11: 54056 | Y11: 262.41 | Z11: 404354 | AA11: 278.29
A12: Medicare A | B12: 276629 | C12: 726.06 | D12: 190410 | E12: 721.25 | F12: 271459 | G12: 696.05 | H12: 231688 | I12: 675.47 | J12: 234861 | K12: 727.13 | L12: 188683 | M12: 681.16 | N12: 195908 | O12: 653.03 | P12: 150286 | Q12: 615.93 | R12: 180454 | S12: 649.11 | T12: 173470 | U12: 649.7 | V12: 165678 | W12: 676.24 | X12: 221112 | Y12: 684.56 | Z12: 2480638 | AA12: 682.43
A13: Commercial Insurance | B13: 106231 | C13: 440.79 | D13: 113904 | E13: 433.09 | F13: 112617 | G13: 415.56 | H13: 58193 | I13: 476.99 | J13: 45675 | K13: 400.66 | L13: 43336 | M13: 577.81 | N13: 52479 | O13: 460.34 | P13: 77254 | Q13: 508.25 | R13: 91873 | S13: 419.51 | T13: 53007 | U13: 486.3 | V13: 50226 | W13: 469.41 | X13: 119379 | Y13: 523.59 | Z13: 924175 | AA13: 458.65
A14: Private Pay | B14: 138594 | C14: 304.6 | D14: 98035 | E14: 304.46 | F14: 102135 | G14: 289.34 | H14: 103587 | I14: 287.74 | J14: 167586 | K14: 287.95 | L14: 140418 | M14: 312.04 | N14: 155881 | O14: 292.46 | P14: 123863 | Q14: 306.59 | R14: 130438 | S14: 299.86 | T14: 104916 | U14: 303.22 | V14: 120531 | W14: 269.64 | X14: 60990 | Y14: 285 | Z14: 1446974 | AA14: 295.24
A15: Veteran Affairs | B15: 0 | D15: 0 | F15: 0 | H15: 0 | J15: 0 | L15: 0 | N15: 0 | P15: 0 | R15: 0 | T15: 0 | V15: 0 | X15: 0 | Z15: 0
A16: Medicare / Managed Care B | B16: 22407 | D16: 1600 | F16: 38819 | H16: 21411 | J16: 26503 | L16: 27290 | N16: 31718 | P16: 29662 | R16: 24022 | T16: 32306 | V16: 18907 | X16: 22468 | Z16: 297113
A17: Private Pay Independent Living | B17: 0 | D17: 0 | F17: 0 | H17: 0 | J17: 0 | L17: 0 | N17: 0 | P17: 0 | R17: 0 | T17: 0 | V17: 0 | X17: 0 | Z17: 0
A18: Home Care Income | B18: 0 | D18: 0 | F18: 0 | H18: 0 | J18: 0 | L18: 0 | N18: 0 | P18: 0 | R18: 0 | T18: 0 | V18: 0 | X18: 0 | Z18: 0
A19: Daily Training Program | B19: 0 | D19: 0 | F19: 0 | H19: 0 | J19: 0 | L19: 0 | N19: 0 | P19: 0 | R19: 0 | T19: 0 | V19: 0 | X19: 0 | Z19: 0
A20: Other | B20: 313 | D20: 1116 | F20: 84 | H20: 82 | J20: 96 | L20: 114 | N20: 87 | P20: 1923 | R20: 139 | T20: 635 | V20: 578 | X20: 108 | Z20: 5276
A21: Stimulus Income | B21: 0 | D21: 0 | F21: 0 | H21: 0 | J21: 0 | L21: 0 | N21: 0 | P21: 0 | R21: 0 | T21: 0 | V21: 0 | X21: 0 | Z21: 0
A22: Incentive Payments | B22: 18506 | C22: 7.21 | D22: 18506 | E22: 7.71 | F22: 18506 | G22: 7.14 | H22: 16901 | I22: 7.5 | J22: 16901 | K22: 6.85 | L22: 16901 | M22: 7.32 | N22: 18546 | O22: 7.81 | P22: 18546 | Q22: 7.94 | R22: 18546 | S22: 7.53 | T22: 18546 | U22: 8.18 | V22: 17166 | W22: 8 | X22: 17856 | Y22: 7.29 | Z22: 215428 | AA22: 7.53
A23: TOTAL Revenue | B23: 974758 | C23: 379.87 | D23: 857852 | E23: 357.29 | F23: 983136 | G23: 379.15 | H23: 835326 | I23: 370.76 | J23: 900903 | K23: 365.33 | L23: 842479 | M23: 364.71 | N23: 877308 | O23: 369.39 | P23: 856113 | Q23: 366.33 | R23: 898468 | S23: 364.93 | T23: 789014 | U23: 347.89 | V23: 723906 | W23: 337.49 | X23: 884982 | Y23: 361.07 | Z23: 10424247 | AA23: 364.14
A24: Patient Days
A25: Medicaid | B25: 1445 | D25: 1459 | F25: 1452 | H25: 1313 | J25: 1315 | L25: 1449 | N25: 1335 | P25: 1397 | R25: 1388 | T25: 1405 | V25: 1225 | X25: 1480 | Z25: 16663
A26: Hospice | B26: 86 | D26: 93 | F26: 120 | H26: 115 | J26: 132 | L26: 65 | N26: 93 | P26: 140 | R26: 142 | T26: 141 | V26: 120 | X26: 206 | Z26: 1453
A27: Medicare A | B27: 381 | D27: 264 | F27: 390 | H27: 343 | J27: 323 | L27: 277 | N27: 300 | P27: 244 | R27: 278 | T27: 267 | V27: 245 | X27: 323 | Z27: 3635
A28: Commercial Insurance | B28: 241 | D28: 263 | F28: 271 | H28: 122 | J28: 114 | L28: 75 | N28: 114 | P28: 152 | R28: 219 | T28: 109 | V28: 107 | X28: 228 | Z28: 2015
A29: Private Pay | B29: 455 | D29: 322 | F29: 353 | H29: 360 | J29: 582 | L29: 450 | N29: 533 | P29: 404 | R29: 435 | T29: 340 | V29: 442 | X29: 218 | Z29: 4894
A30: Veteran Affairs | B30: 0 | D30: 0 | F30: 0 | H30: 0 | J30: 0 | L30: 0 | N30: 0 | P30: 0 | R30: 0 | T30: 0 | V30: 0 | X30: 0 | Z30: 0
A31: Independent Living | B31: 0 | D31: 0 | F31: 0 | H31: 0 | J31: 0 | L31: 0 | N31: 0 | P31: 0 | R31: 0 | T31: 0 | V31: 0 | X31: 0 | Z31: 0
A32: TOTAL Patient Days | B32: 2608 | D32: 2401 | F32: 2586 | H32: 2253 | J32: 2466 | L32: 2316 | N32: 2375 | P32: 2337 | R32: 2462 | T32: 2262 | V32: 2139 | X32: 2455 | Z32: 28660
A33: Nursing & Medical
A34: Director Of Nursing | B34: 9212 | C34: 3.59 | D34: 7717 | E34: 3.21 | F34: 8952 | G34: 3.45 | H34: 8492 | I34: 3.77 | J34: 8997 | K34: 3.65 | L34: 8509 | M34: 3.68 | N34: 10067 | O34: 4.24 | P34: 8597 | Q34: 3.68 | R34: 8438 | S34: 3.43 | T34: 9040 | U34: 3.99 | V34: 9054 | W34: 4.22 | X34: 8871 | Y34: 3.62 | Z34: 105946 | AA34: 3.7
A35: Assistant Director Of Nursing | B35: 7877 | C35: 3.07 | D35: 7354 | E35: 3.06 | F35: 7832 | G35: 3.02 | H35: 7552 | I35: 3.35 | J35: 8298 | K35: 3.36 | L35: 7532 | M35: 3.26 | N35: 7601 | O35: 3.2 | P35: 7638 | Q35: 3.27 | R35: 6659 | S35: 2.7 | T35: 1904 | U35: 0.84 | V35: 6738 | W35: 3.14 | X35: 8630 | Y35: 3.52 | Z35: 85613 | AA35: 2.99
A36: Payroll RN | B36: 65236 | C36: 25.42 | D36: 60365 | E36: 25.14 | F36: 68632 | G36: 26.47 | H36: 69671 | I36: 30.92 | J36: 71475 | K36: 28.98 | L36: 69227 | M36: 29.97 | N36: 72869 | O36: 30.68 | P36: 66824 | Q36: 28.59 | R36: 64087 | S36: 26.03 | T36: 66427 | U36: 29.29 | V36: 64275 | W36: 29.97 | X36: 61682 | Y36: 25.17 | Z36: 800771 | AA36: 27.97
A37: Payroll LPN | B37: 36740 | C37: 14.32 | D37: 36131 | E37: 15.05 | F37: 35983 | G37: 13.88 | H37: 33791 | I37: 15 | J37: 33989 | K37: 13.78 | L37: 40210 | M37: 17.41 | N37: 34691 | O37: 14.61 | P37: 34825 | Q37: 14.9 | R37: 35716 | S37: 14.51 | T37: 40897 | U37: 18.03 | V37: 39372 | W37: 18.36 | X37: 40479 | Y37: 16.52 | Z37: 442824 | AA37: 15.47
A38: Payroll Aides & Orderlies | B38: 158997 | C38: 61.96 | D38: 131266 | E38: 54.67 | F38: 156709 | G38: 60.44 | H38: 157935 | I38: 70.1 | J38: 171345 | K38: 69.48 | L38: 162985 | M38: 70.56 | N38: 155904 | O38: 65.64 | P38: 145993 | Q38: 62.47 | R38: 154712 | S38: 62.84 | T38: 142246 | U38: 62.72 | V38: 151314 | W38: 70.54 | X38: 172369 | Y38: 70.33 | Z38: 1861774 | AA38: 65.04
A39: Payroll Nursing Clerical | B39: 7723 | C39: 3.01 | D39: 7800 | E39: 3.25 | F39: 7670 | G39: 2.96 | H39: 7340 | I39: 3.26 | J39: 8444 | K39: 3.42 | L39: 7123 | M39: 3.08 | N39: 7715 | O39: 3.25 | P39: 7615 | Q39: 3.26 | R39: 7479 | S39: 3.04 | T39: 7624 | U39: 3.36 | V39: 7485 | W39: 3.49 | X39: 8478 | Y39: 3.46 | Z39: 92496 | AA39: 3.23
A40: Payroll Medical Records | B40: 0 | C40: 0 | D40: 0 | E40: 0 | F40: 0 | G40: 0 | H40: 0 | I40: 0 | J40: 0 | K40: 0 | L40: 0 | M40: 0 | N40: 0 | O40: 0 | P40: 0 | Q40: 0 | R40: 0 | S40: 0 | T40: 0 | U40: 0 | V40: 0 | W40: 0 | X40: 0 | Y40: 0 | Z40: 0 | AA40: 0
A41: Contract RN | B41: 24990 | C41: 9.74 | D41: 10031 | E41: 4.18 | F41: 15243 | G41: 5.88 | H41: 4530 | I41: 2.01 | J41: 15581 | K41: 6.32 | L41: 13713 | M41: 5.94 | N41: 13755 | O41: 5.79 | P41: 5793 | Q41: 2.48 | R41: 26888 | S41: 10.92 | T41: 12299 | U41: 5.42 | V41: 8223 | W41: 3.83 | X41: 26644 | Y41: 10.87 | Z41: 177691 | AA41: 6.21
A42: Contract LPN | B42: 7758 | C42: 3.02 | D42: 1974 | E42: 0.82 | F42: 3687 | G42: 1.42 | H42: 0 | I42: 0 | J42: 1264 | K42: 0.51 | L42: 193 | M42: 0.08 | N42: 882 | O42: 0.37 | P42: 0 | Q42: 0 | R42: 0 | S42: 0 | T42: 260 | U42: 0.11 | V42: 0 | W42: 0 | X42: 2399 | Y42: 0.98 | Z42: 18418 | AA42: 0.64
...

Sheet PR Trending Data
A1: ?"Date: May 8 | B1: 2026" | C1: Allure of Peru | D1: Facility #IL6004303
A2: Time: 12:09:08 EDT | B2: Payroll Summary Detail-GGM
A3: User: Roth - Tracy Morkunas | B3: 1/1/2025 to 12/31/2025
A5: Include Adjustment Periods: NO | B5: Include Closing Periods: NO
B7: January 25_Actual $ | C7: January 25_Actual / Day | D7: February 25_Actual $ | E7: February 25_Actual / Day | F7: March 25_Actual $ | G7: March 25_Actual / Day | H7: April 25_Actual $ | I7: April 25_Actual / Day | J7: May 25_Actual $ | K7: May 25_Actual / Day | L7: June 25_Actual $ | M7: June 25_Actual / Day | N7: July 25_Actual $ | O7: July 25_Actual / Day | P7: August 25_Actual $ | Q7: August 25_Actual / Day | R7: September 25_Actual $ | S7: September 25_Actual / Day | T7: October 25_Actual $ | U7: October 25_Actual / Day | V7: November 25_Actual $ | W7: November 25_Actual / Day | X7: December 25_Actual $ | Y7: December 25_Actual / Day | Z7: TOTALS_Actual $ | AA7: TOTALS_Actual / Day
A8: Payroll Summary
A9: P/R Administrator | B9: 10221 | C9: 3.98 | D9: 9232 | E9: 3.85 | F9: 10241 | G9: 3.95 | H9: 10188 | I9: 4.52 | J9: 10528 | K9: 4.27 | L9: 10188 | M9: 4.41 | N9: 10528 | O9: 4.43 | P9: 10528 | Q9: 4.5 | R9: 10188 | S9: 4.14 | T9: 10528 | U9: 4.64 | V9: 10188 | W9: 4.75 | X9: 11658 | Y9: 4.76 | Z9: 124215 | AA9: 4.34
A10: P/R Administrator Covid | B10: 1922 | C10: 0.75 | D10: 1487 | E10: 0.62 | F10: 113 | G10: 0.04 | H10: 2287 | I10: 1.02 | J10: 1608 | K10: 0.65 | L10: 1871 | M10: 0.81 | N10: 1014 | O10: 0.43 | P10: 1741 | Q10: 0.74 | R10: 303 | S10: 0.12 | T10: 1606 | U10: 0.71 | V10: 659 | W10: 0.31 | X10: 0 | Y10: 0 | Z10: 14610 | AA10: 0.51
A11: P/R Assistant Admin Covid | B11: 0 | C11: 0 | D11: 0 | E11: 0 | F11: 0 | G11: 0 | H11: 0 | I11: 0 | J11: 0 | K11: 0 | L11: 0 | M11: 0 | N11: 0 | O11: 0 | P11: 0 | Q11: 0 | R11: 0 | S11: 0 | T11: 0 | U11: 0 | V11: 0 | W11: 0 | X11: 0 | Y11: 0 | Z11: 0 | AA11: 0
A12: P/R Assistant Administrator | B12: 0 | C12: 0 | D12: 0 | E12: 0 | F12: 0 | G12: 0 | H12: 0 | I12: 0 | J12: 0 | K12: 0 | L12: 0 | M12: 0 | N12: 0 | O12: 0 | P12: 0 | Q12: 0 | R12: 0 | S12: 0 | T12: 0 | U12: 0 | V12: 0 | W12: 0 | X12: 0 | Y12: 0 | Z12: 0 | AA12: 0
A13: P/R DON | B13: 9212 | C13: 3.59 | D13: 7717 | E13: 3.21 | F13: 8952 | G13: 3.45 | H13: 8492 | I13: 3.77 | J13: 8997 | K13: 3.65 | L13: 8509 | M13: 3.68 | N13: 8817 | O13: 3.71 | P13: 8597 | Q13: 3.68 | R13: 8438 | S13: 3.43 | T13: 8719 | U13: 3.84 | V13: 8626 | W13: 4.02 | X13: 8871 | Y13: 3.62 | Z13: 103946 | AA13: 3.63
